Workbook

Sheet Fieldwork W1
A1: Week 1
A3: Group 1 | B3: Rand | C3: Respuesta 1 | D3: Repuesta 2 | E3: Repuesta 3 | F3: Repuesta 4 | G3: Repuesta 5 | H3: Repuesta 6 | I3: Respuesta 7 | J3: Respuesta 8 | K3: Respuesta 9 | L3: Respuesta 10
A4: P11 | B4: 0.020097957 | C4: A | D4: A | E4: B | F4: A | G4: A | H4: A | I4: A | J4: B | K4: B* | L4: B
A5: P35 | B5: 0.024842132 | C5: A | D5: B | E5: B | F5: B | G5: A | H5: A | J5: B | K5: A | L5: A
A6: P29 | B6: 0.079354253 | C6: A | D6: B | F6: B | G6: A | H6: A | I6: A | J6: B | K6: B | L6: B
A7: P01 | B7: 0.12628297 | C7: A | D7: B | E7: B | F7: B | G7: A | H7: B | I7: A | J7: B | K7: A | L7: B
A8: P08 | B8: 0.13432477 | C8: A | D8: B | E8: B | F8: B | G8: B | H8: A | I8: A | J8: B | K8: A | L8: B
A9: P07 | B9: 0.19358816 | C9: A | D9: B | E9: B | F9: B | G9: A | H9: B | I9: A | J9: B | K9: B | L9: B
A10: P05 | B10: 0.19889441 | C10: A | D10: B | E10: B | F10: B | G10: B | H10: A | I10: A | J10: A | K10: B | L10: A
A11: P37 | B11: 0.22664409 | C11: B | D11: B | E11: B | F11: B | G11: A | H11: A | I11: A | J11: B | K11: A | L11: B
A12: P38 | B12: 0.25531081 | D12: A | E12: B | F12: A | G12: A | H12: A | I12: A | J12: B | K12: A | L12: A
A13: P24 | B13: 0.35644461 | C13: B | D13: B | E13: B | G13: A | H13: A | I13: A | J13: B | K13: A | L13: B
A14: P19 | B14: 0.37449264 | C14: B | D14: A | E14: B | F14: A | G14: A | H14: B | I14: B | J14: A | K14: A | L14: A
A15: P34 | B15: 0.40069635 | C15: B | D15: B | E15: A | F15: A | G15: A | H15: B | I15: A | J15: B | K15: A | L15: B
A16: P15 | B16: 0.40260066 | C16: A | D16: B | E16: B | F16: B | G16: A | H16: B | J16: B | K16: B | L16: A
A17: P21 | B17: 0.42864642 | G17: A | H17: A | I17: A | J17: A | K17: A | L17: A
A18: P04 | B18: 0.43661553 | J18: B | K18: B | L18: B
A19: P32 | B19: 0.4595524 | C19: A | D19: B | E19: A | F19: B | G19: A | H19: A | I19: A | J19: B | K19: B | L19: B
A20: P17 | B20: 0.47239587 | C20: A | D20: B | E20: B | F20: B | G20: A | H20: A | I20: A | J20: A | K20: A | L20: B
A21: P20 | B21: 0.4762543 | C21: A | D21: B | E21: B | F21: B | G21: A | H21: A | I21: A | J21: B | K21: B | L21: A
A22: P13 | B22: 0.49803295 | C22: A | D22: B | E22: B | F22: B | G22: B | H22: A | I22: A | J22: A | K22: B | L22: A
A27: Group 2 | B27: Rand | C27: Respuesta | D27: Respuesta 2 | E27: Respuesta 3 | F27: Repuesta 4 | G27: Repuesta 5 | H27: Repuesta 6 | I27: Respuesta 7 | J27: Respuesta 8 | K27: Respuesta 9 | L27: Respuesta 10
A28: P12 | B28: 0.53187416 | C28: A | D28: A | E28: A | F28: A | G28: A | H28: B | I28: B | J28: A | K28: B | L28: A
A29: P25 | B29: 0.5387171 | C29: A | D29: B | E29: A | F29: B | G29: A | H29: A | I29: B | J29: A | K29: A | L29: A
A30: P16 | B30: 0.54909977 | C30: A | D30: B | E30: B | F30: A | G30: B | H30: A | I30: A | J30: A | K30: A | L30: A
A31: P14 | B31: 0.57665292 | C31: A | D31: A | E31: B | F31: A | G31: A | H31: A | I31: B | J31: A | K31: A | L31: A
A32: P30 | B32: 0.67697 | C32: A | D32: B | E32: B | F32: B | G32: A | H32: A | I32: B | J32: A | K32: A | L32: A
A33: P26 | B33: 0.70019322 | C33: A | D33: B | E33: A | F33: A | G33: B | H33: A | I33: B | J33: B | K33: A | L33: A
A34: P36 | B34: 0.72556564 | J34: B | L34: A
A35: P33 | B35: 0.7504248 | C35: A | D35: B | E35: B | F35: A | G35: A | H35: A | I35: B | J35: B | K35: A | L35: A
A36: P03 | B36: 0.754012 | C36: A | D36: A | E36: A | F36: A | G36: A | H36: A | I36: B | J36: A | K36: A | L36: A
A37: P18 | B37: 0.7865677 | D37: B* | E37: B | F37: B | G37: A | H37: A | I37: B | J37: A | K37: A | L37: A
A38: P02 | B38: 0.78962594 | C38: A | D38: B | E38: B | F38: A | G38: B | H38: A | I38: B | J38: A | K38: A | L38: B
A39: P22 | B39: 0.87755231 | C39: A | D39: B | E39: A | F39: B | G39: A | H39: A | I39: B | K39: A | L39: A
A40: P10 | B40: 0.90188052 | C40: A | D40: B | E40: A | F40: A | G40: A | H40: A | I40: A | J40: B | K40: A | L40: A
A41: P23 | B41: 0.91512981 | C41: A | D41: B | E41: B | F41: A | G41: B | H41: A | I41: A | J41: A | K41: A | L41: A
A42: P06 | B42: 0.92448101 | C42: A* | D42: A | E42: A | F42: A | G42: A | H42: A* | I42: A | J42: B | K42: A* | L42: A
A43: P31 | B43: 0.93288114 | C43: A | D43: B | E43: B | F43: A | G43: B | H43: A | I43: B | J43: A | K43: B | L43: A
A44: P27 | B44: 0.95961973 | C44: A | D44: B | E44: B | F44: A | G44: B | H44: B | I44: B | J44: B | K44: A | L44: A
A45: P28 | B45: 0.98247961 | J45: A | K45: A | L45: B
...

Sheet Fieldwork W2
A1: Week 1
A3: Group 1 | B3: Rand | C3: Respuesta 1 | D3: Repuesta 2 | E3: Repuesta 3 | F3: Repuesta 4 | G3: Repuesta 5 | H3: Repuesta 6 | I3: Respuesta 7 | J3: Respuesta 8 | K3: Respuesta 9 | L3: Respuesta 10
A4: P31 | B4: 0.0072936031 | C4: A | D4: B | E4: A | G4: A | H4: B | I4: B | J4: A | K4: B | L4: A
A5: P10 | B5: 0.046863232 | C5: A | D5: A | E5: B | F5: A | G5: B | H5: B | I5: A | J5: A | K5: A | L5: A
A6: P09 | B6: 0.070849874 | C6: A | D6: A* | E6: A* | F6: A | G6: A | H6: B | I6: B | J6: A | K6: B
A7: P27 | B7: 0.077050466 | C7: B | D7: B | E7: A | F7: B | G7: A | H7: B | I7: B | J7: A | K7: A | L7: A
A8: P21 | B8: 0.1104865 | C8: B | D8: A | E8: A | F8: B | G8: A | H8: A | I8: A | J8: A | K8: A | L8: B
A9: P38 | B9: 0.12790664
A10: P22 | B10: 0.14018244 | D10: A | E10: B | F10: B | G10: A | H10: B | I10: A | J10: A | K10: A | L10: A
A11: P36 | B11: 0.16719983 | C11: A | D11: B | E11: A | F11: A | G11: A | H11: B | I11: B | J11: A | L11: A
A12: P28 | B12: 0.16731448 | C12: A | D12: B | E12: B | F12: A | G12: A | H12: B | I12: B | J12: A | K12: A | L12: B
A13: P24 | B13: 0.20316417 | C13: A | D13: B | E13: B | F13: A | G13: A | H13: B | I13: B | J13: A | K13: A | L13: B
A14: P26 | B14: 0.21371424 | C14: A | D14: B | E14: A | F14: A | G14: A | H14: B | I14: B | J14: A | K14: A | L14: A
A15: P04 | B15: 0.22091551 | C15: A | D15: B | E15: A | F15: A | G15: A | H15: B | I15: B | J15: A | K15: A | L15: B
A16: P33 | B16: 0.27030766 | C16: A | D16: A | E16: A | F16: B | G16: A | H16: B | I16: B | J16: A | K16: A | L16: B
A17: P08 | B17: 0.29939042 | C17: A | D17: B* | E17: A | F17: A | H17: B | I17: B | J17: A | K17: A | L17: B
A18: P30 | B18: 0.34327104 | C18: A | D18: A | E18: A | F18: B | G18: A | H18: A | I18: B | J18: A | K18: A
A19: P11 | B19: 0.36864346 | C19: B | D19: A | E19: A | F19: B | G19: A | H19: B | I19: A | J19: B | K19: A | L19: B
A20: P05 | B20: 0.40496613 | C20: A | D20: B | E20: A | F20: A | G20: B | H20: A | I20: B | J20: A* | K20: A | L20: B
A21: P34 | B21: 0.44540539 | C21: A | D21: A | E21: B | F21: A | H21: B | I21: A | J21: A | K21: A | L21: A
A22: P03 | B22: 0.4716115 | D22: A | E22: B | F22: B | G22: A | H22: A | I22: A | J22: A | K22: A | L22: A
A27: Group 2 | B27: Rand | C27: Respuesta | D27: Respuesta 2 | E27: Respuesta 3 | F27: Repuesta 4 | G27: Repuesta 5 | H27: Repuesta 6 | I27: Respuesta 7 | J27: Respuesta 8 | K27: Respuesta 9 | L27: Respuesta 10
A28: P35 | B28: 0.47219708 | C28: B | D28: A | E28: B | F28: A | G28: B | H28: A | I28: A | J28: A | K28: A | L28: A
A29: P07 | B29: 0.53696252 | C29: A | D29: B | E29: B | F29: A | G29: B | H29: B | I29: A | J29: A | K29: B | L29: A
A30: P20 | B30: 0.61510106 | C30: A | D30: B | E30: A | F30: A | G30: B | H30: A | I30: A | J30: A | K30: A | L30: A
A31: P29 | B31: 0.67377177 | C31: A | D31: B | E31: B | F31: A | G31: B | H31: B | I31: B | J31: A | K31: B
A32: P02 | B32: 0.70302744 | C32: B | D32: A | E32: A | F32: A | G32: B | H32: B* | I32: B | J32: B | K32: B | L32: A
A33: P18 | B33: 0.79441754 | C33: A | D33: A | E33: A | F33: A | G33: A | H33: A | I33: A | J33: A | K33: A | L33: A
A34: P15 | B34: 0.81352587 | C34: A | D34: A | E34: B | F34: A | H34: B | I34: A | J34: A | K34: A | L34: A
A35: P37 | B35: 0.8368246 | C35: B | D35: B* | E35: B | H35: A | I35: B | J35: A | K35: B | L35: A
A36: P01 | B36: 0.84563926 | C36: B | D36: B | E36: B | F36: A | G36: B | H36: B | I36: B | J36: A | K36: B | L36: B
A37: P19 | B37: 0.84653413 | C37: A | D37: A | E37: A | F37: A | H37: B | I37: A | J37: A | K37: A | L37: A
A38: P12 | B38: 0.87524851 | D38: B | E38: B | F38: A | G38: B | H38: A | I38: A | J38: A | K38: B | L38: A
A39: P14 | B39: 0.89003449 | C39: A | D39: B | E39: A | F39: A | G39: B | H39: B | I39: A | J39: A | K39: B | L39: A
A40: P13 | B40: 0.91187638 | C40: B | D40: A | E40: A | F40: A | G40: A | H40: A | I40: A | J40: A | K40: A | L40: A
A41: P25 | B41: 0.92646301 | C41: A | D41: B | E41: B | F41: A | G41: B | H41: B* | I41: A | J41: A | K41: B | L41: A
A42: P06 | B42: 0.93488827 | C42: A* | D42: A* | E42: B* | F42: B | G42: A | H42: B | I42: A | J42: A | K42: A | L42: A
A43: P17 | B43: 0.93715089 | C43: B | D43: A | E43: A | G43: A | H43: A | I43: B | J43: A | K43: A | L43: A
A44: P23 | B44: 0.98984076 | C44: ______ | K44: A | L44: A
A45: P32 | B45: 0.9962195 | C45: A | D45: B | E45: B | F45: A | H45: A | I45: B | J45: A | K45: B | L45: A
...

Sheet DATA
A1: ID | B1: w1 | C1: w2 | D1: group | E1: e1 | F1: e2 | G1: e3 | H1: e4 | I1: e5 | J1: e6 | K1: e7 | L1: e8 | M1: e9 | N1: e10 | O1: e11 | P1: e12 | Q1: e13 | R1: e14 | S1: e15 | T1: e16 | U1: e17 | V1: e18 | W1: e19 | X1: e20 | Y1: resp_rate | Z1: a1 | AA1: a2 | AB1: a3 | AC1: a4 | AD1: a5 | AE1: a6 | AF1: a7 | AG1: a8 | AH1: a9 | AI1: a10 | AJ1: a11 | AK1: a12 | AL1: a13 | AM1: a14 | AN1: a15 | AO1: a16 | AP1: a17 | AQ1: a18 | AR1: a19 | AS1: a20 | AT1: accuracy | AU1: responded | AV1: correct
A2: P01 | B2: =IF(COUNTIF('Fieldwork W1'!$A$4:$A$22, A2) > 0, "1", IF(COUNTIF('Fieldwork W1'!$A$28:$A$46, A2) > 0, "2", "")) -> 1 | C2: =IF(COUNTIF('Fieldwork W2'!$A$4:$A$22, A2) > 0, "1", IF(COUNTIF('Fieldwork W2'!$A$28:$A$46, A2) > 0, "2", "")) -> 2 | D2: =B2&C2 -> 12 | E2: A | F2: B | G2: B | H2: B | I2: A | J2: B | K2: A | L2: B | M2: A | N2: B | O2: B | P2: B | Q2: B | R2: A | S2: B | T2: B | U2: B | V2: A | W2: B | X2: B | Y2: =(COUNTIF(E2:X2,"A")+COUNTIF(E2:X2,"B"))/20 -> 1 | Z2: =IF(ISBLANK(E2),"",IF(E2=Truth!B$23,1,0)) -> 1 | AA2: =IF(ISBLANK(F2),"",IF(F2=Truth!C$23,1,0)) -> 1 | AB2: =IF(ISBLANK(G2),"",IF(G2=Truth!D$23,1,0)) -> 1 | AC2: =IF(ISBLANK(H2),"",IF(H2=Truth!E$23,1,0)) -> 1 | AD2: =IF(ISBLANK(I2),"",IF(I2=Truth!F$23,1,0)) -> 1 | AE2: =IF(ISBLANK(J2),"",IF(J2=Truth!G$23,1,0)) -> 0 | AF2: =IF(ISBLANK(K2),"",IF(K2=Truth!H$23,1,0)) -> 1 | AG2: =IF(ISBLANK(L2),"",IF(L2=Truth!I$23,1,0)) -> 1 | ... AS2: =IF(ISBLANK(X2),"",IF(X2=Truth!U$23,1,0)) -> 0 | AT2: =AVERAGE(Z2:AS2) -> 0.8 | AU2: {=SUM(N(LEN(TRIM(Z2:AS2))>0))} -> 20 | AV2: =sum(Z2:AS2) -> 16
A3: P02 | B3: =IF(COUNTIF('Fieldwork W1'!$A$4:$A$22, A3) > 0, "1", IF(COUNTIF('Fieldwork W1'!$A$28:$A$46, A3) > 0, "2", "")) -> 2 | C3: =IF(COUNTIF('Fieldwork W2'!$A$4:$A$22, A3) > 0, "1", IF(COUNTIF('Fieldwork W2'!$A$28:$A$46, A3) > 0, "2", "")) -> 2 | D3: =B3&C3 -> 22 | E3: A | F3: B | G3: B | H3: A | I3: B | J3: A | K3: B | L3: A | M3: A | N3: B | O3: B | P3: A | Q3: A | R3: A | S3: B | U3: B | V3: B | W3: B | X3: A | Y3: =(COUNTIF(E3:X3,"A")+COUNTIF(E3:X3,"B"))/20 -> 0.95 | Z3: =IF(ISBLANK(E3),"",IF(E3=Truth!B$25,1,0)) -> 1 | AA3: =IF(ISBLANK(F3),"",IF(F3=Truth!C$25,1,0)) -> 1 | AB3: =IF(ISBLANK(G3),"",IF(G3=Truth!D$25,1,0)) -> 1 | AC3: =IF(ISBLANK(H3),"",IF(H3=Truth!E$25,1,0)) -> 0 | AD3: =IF(ISBLANK(I3),"",IF(I3=Truth!F$25,1,0)) -> 0 | AE3: =IF(ISBLANK(J3),"",IF(J3=Truth!G$25,1,0)) -> 1 | AF3: =IF(ISBLANK(K3),"",IF(K3=Truth!H$25,1,0)) -> 1 | AG3: =IF(ISBLANK(L3),"",IF(L3=Truth!I$25,1,0)) -> 0 | ... AS3: =IF(ISBLANK(X3),"",IF(X3=Truth!U$25,1,0)) -> 1 | AT3: =AVERAGE(Z3:AS3) -> 0.68421053 | AU3: {=SUM(N(LEN(TRIM(Z3:AS3))>0))} -> 19 | AV3: =sum(Z3:AS3) -> 13
A4: P03 | B4: =IF(COUNTIF('Fieldwork W1'!$A$4:$A$22, A4) > 0, "1", IF(COUNTIF('Fieldwork W1'!$A$28:$A$46, A4) > 0, "2", "")) -> 2 | C4: =IF(COUNTIF('Fieldwork W2'!$A$4:$A$22, A4) > 0, "1", IF(COUNTIF('Fieldwork W2'!$A$28:$A$46, A4) > 0, "2", "")) -> 1 | D4: =B4&C4 -> 21 | E4: A | F4: A | G4: A | H4: A | I4: A | J4: A | K4: B | L4: A | M4: A | N4: A | P4: A | Q4: B | R4: B | S4: A | T4: A | U4: A | V4: A | W4: A | X4: A | Y4: =(COUNTIF(E4:X4,"A")+COUNTIF(E4:X4,"B"))/20 -> 0.95 | Z4: =IF(ISBLANK(E4),"",IF(E4=Truth!B$24,1,0)) -> 1 | AA4: =IF(ISBLANK(F4),"",IF(F4=Truth!C$24,1,0)) -> 0 | AB4: =IF(ISBLANK(G4),"",IF(G4=Truth!D$24,1,0)) -> 0 | AC4: =IF(ISBLANK(H4),"",IF(H4=Truth!E$24,1,0)) -> 0 | AD4: =IF(ISBLANK(I4),"",IF(I4=Truth!F$24,1,0)) -> 1 | AE4: =IF(ISBLANK(J4),"",IF(J4=Truth!G$24,1,0)) -> 1 | AF4: =IF(ISBLANK(K4),"",IF(K4=Truth!H$24,1,0)) -> 1 | AG4: =IF(ISBLANK(L4),"",IF(L4=Truth!I$24,1,0)) -> 0 | ... AS4: =IF(ISBLANK(X4),"",IF(X4=Truth!U$24,1,0)) -> 1 | AT4: =AVERAGE(Z4:AS4) -> 0.52631579 | AU4: {=SUM(N(LEN(TRIM(Z4:AS4))>0))} -> 19 | AV4: =sum(Z4:AS4) -> 10
A5: P04 | B5: =IF(COUNTIF('Fieldwork W1'!$A$4:$A$22, A5) > 0, "1", IF(COUNTIF('Fieldwork W1'!$A$28:$A$46, A5) > 0, "2", "")) -> 1 | C5: =IF(COUNTIF('Fieldwork W2'!$A$4:$A$22, A5) > 0, "1", IF(COUNTIF('Fieldwork W2'!$A$28:$A$46, A5) > 0, "2", "")) -> 1 | D5: =B5&C5 -> 11 | L5: B | M5: B | N5: B | O5: A | P5: B | Q5: A | R5: A | S5: A | T5: B | U5: B | V5: A | W5: A | X5: B | Y5: =(COUNTIF(E5:X5,"A")+COUNTIF(E5:X5,"B"))/20 -> 0.65 | Z5: =IF(ISBLANK(E5),"",IF(E5=Truth!B$22,1,0)) | AA5: =IF(ISBLANK(F5),"",IF(F5=Truth!C$22,1,0)) | AB5: =IF(ISBLANK(G5),"",IF(G5=Truth!D$22,1,0)) | AC5: =IF(ISBLANK(H5),"",IF(H5=Truth!E$22,1,0)) | AD5: =IF(ISBLANK(I5),"",IF(I5=Truth!F$22,1,0)) | AE5: =IF(ISBLANK(J5),"",IF(J5=Truth!G$22,1,0)) | AF5: =IF(ISBLANK(K5),"",IF(K5=Truth!H$22,1,0)) | AG5: =IF(ISBLANK(L5),"",IF(L5=Truth!I$22,1,0)) -> 1 | ... AS5: =IF(ISBLANK(X5),"",IF(X5=Truth!U$22,1,0)) -> 0 | AT5: =AVERAGE(Z5:AS5) -> 0.69230769 | AU5: {=SUM(N(LEN(TRIM(Z5:AS5))>0))} -> 13 | AV5: =sum(Z5:AS5) -> 9
A6: P05 | B6: =IF(COUNTIF('Fieldwork W1'!$A$4:$A$22, A6) > 0, "1", IF(COUNTIF('Fieldwork W1'!$A$28:$A$46, A6) > 0, "2", "")) -> 1 | C6: =IF(COUNTIF('Fieldwork W2'!$A$4:$A$22, A6) > 0, "1", IF(COUNTIF('Fieldwork W2'!$A$28:$A$46, A6) > 0, "2", "")) -> 1 | D6: =B6&C6 -> 11 | E6: A | F6: B | G6: B | H6: B | I6: B | J6: A | K6: A | L6: A | M6: B | N6: A | O6: A | P6: B | Q6: A | R6: A | S6: B | T6: A | U6: B | W6: A | X6: B | Y6: =(COUNTIF(E6:X6,"A")+COUNTIF(E6:X6,"B"))/20 -> 0.95 | Z6: =IF(ISBLANK(E6),"",IF(E6=Truth!B$22,1,0)) -> 1 | AA6: =IF(ISBLANK(F6),"",IF(F6=Truth!C$22,1,0)) -> 1 | AB6: =IF(ISBLANK(G6),"",IF(G6=Truth!D$22,1,0)) -> 1 | AC6: =IF(ISBLANK(H6),"",IF(H6=Truth!E$22,1,0)) -> 1 | AD6: =IF(ISBLANK(I6),"",IF(I6=Truth!F$22,1,0)) -> 0 | AE6: =IF(ISBLANK(J6),"",IF(J6=Truth!G$22,1,0)) -> 1 | AF6: =IF(ISBLANK(K6),"",IF(K6=Truth!H$22,1,0)) -> 1 | AG6: =IF(ISBLANK(L6),"",IF(L6=Truth!I$22,1,0)) -> 0 | ... AS6: =IF(ISBLANK(X6),"",IF(X6=Truth!U$22,1,0)) -> 0 | AT6: =AVERAGE(Z6:AS6) -> 0.52631579 | AU6: {=SUM(N(LEN(TRIM(Z6:AS6))>0))} -> 19 | AV6: =sum(Z6:AS6) -> 10
A7: P06 | B7: =IF(COUNTIF('Fieldwork W1'!$A$4:$A$22, A7) > 0, "1", IF(COUNTIF('Fieldwork W1'!$A$28:$A$46, A7) > 0, "2", "")) -> 2 | C7: =IF(COUNTIF('Fieldwork W2'!$A$4:$A$22, A7) > 0, "1", IF(COUNTIF('Fieldwork W2'!$A$28:$A$46, A7) > 0, "2", "")) -> 2 | D7: =B7&C7 -> 22 | F7: A | G7: A | H7: A | I7: A | K7: A | L7: B | N7: A | R7: B | S7: A | T7: B | U7: A | V7: A | W7: A | X7: A | Y7: =(COUNTIF(E7:X7,"A")+COUNTIF(E7:X7,"B"))/20 -> 0.7 | Z7: =IF(ISBLANK(E7),"",IF(E7=Truth!B$25,1,0)) | AA7: =IF(ISBLANK(F7),"",IF(F7=Truth!C$25,1,0)) -> 0 | AB7: =IF(ISBLANK(G7),"",IF(G7=Truth!D$25,1,0)) -> 0 | AC7: =IF(ISBLANK(H7),"",IF(H7=Truth!E$25,1,0)) -> 0 | AD7: =IF(ISBLANK(I7),"",IF(I7=Truth!F$25,1,0)) -> 1 | AE7: =IF(ISBLANK(J7),"",IF(J7=Truth!G$25,1,0)) | AF7: =IF(ISBLANK(K7),"",IF(K7=Truth!H$25,1,0)) -> 0 | AG7: =IF(ISBLANK(L7),"",IF(L7=Truth!I$25,1,0)) -> 1 | ... AS7: =IF(ISBLANK(X7),"",IF(X7=Truth!U$25,1,0)) -> 1 | AT7: =AVERAGE(Z7:AS7) -> 0.35714286 | AU7: {=SUM(N(LEN(TRIM(Z7:AS7))>0))} -> 14 | AV7: =sum(Z7:AS7) -> 5
A8: P07 | B8: =IF(COUNTIF('Fieldwork W1'!$A$4:$A$22, A8) > 0, "1", IF(COUNTIF('Fieldwork W1'!$A$28:$A$46, A8) > 0, "2", "")) -> 1 | C8: =IF(COUNTIF('Fieldwork W2'!$A$4:$A$22, A8) > 0, "1", IF(COUNTIF('Fieldwork W2'!$A$28:$A$46, A8) > 0, "2", "")) -> 2 | D8: =B8&C8 -> 12 | E8: A | F8: B | G8: B | H8: B | I8: A | J8: B | K8: A | L8: B | M8: B | N8: B | O8: A | P8: B | Q8: B | R8: A | S8: B | T8: B | U8: A | V8: A | W8: B | X8: A | Y8: =(COUNTIF(E8:X8,"A")+COUNTIF(E8:X8,"B"))/20 -> 1 | Z8: =IF(ISBLANK(E8),"",IF(E8=Truth!B$23,1,0)) -> 1 | AA8: =IF(ISBLANK(F8),"",IF(F8=Truth!C$23,1,0)) -> 1 | AB8: =IF(ISBLANK(G8),"",IF(G8=Truth!D$23,1,0)) -> 1 | AC8: =IF(ISBLANK(H8),"",IF(H8=Truth!E$23,1,0)) -> 1 | AD8: =IF(ISBLANK(I8),"",IF(I8=Truth!F$23,1,0)) -> 1 | AE8: =IF(ISBLANK(J8),"",IF(J8=Truth!G$23,1,0)) -> 0 | AF8: =IF(ISBLANK(K8),"",IF(K8=Truth!H$23,1,0)) -> 1 | AG8: =IF(ISBLANK(L8),"",IF(L8=Truth!I$23,1,0)) -> 1 | ... AS8: =IF(ISBLANK(X8),"",IF(X8=Truth!U$23,1,0)) -> 1 | AT8: =AVERAGE(Z8:AS8) -> 0.7 | AU8: {=SUM(N(LEN(TRIM(Z8:AS8))>0))} -> 20 | AV8: =sum(Z8:AS8) -> 14
A9: P08 | B9: =IF(COUNTIF('Fieldwork W1'!$A$4:$A$22, A9) > 0, "1", IF(COUNTIF('Fieldwork W1'!$A$28:$A$46, A9) > 0, "2", "")) -> 1 | C9: =IF(COUNTIF('Fieldwork W2'!$A$4:$A$22, A9) > 0, "1", IF(COUNTIF('Fieldwork W2'!$A$28:$A$46, A9) > 0, "2", "")) -> 1 | D9: =B9&C9 -> 11 | E9: A | F9: B | G9: B | H9: B | I9: B | J9: A | K9: A | L9: B | M9: A | N9: B | O9: A | Q9: A | R9: A | T9: B | U9: B | V9: A | W9: A | X9: B | Y9: =(COUNTIF(E9:X9,"A")+COUNTIF(E9:X9,"B"))/20 -> 0.9 | Z9: =IF(ISBLANK(E9),"",IF(E9=Truth!B$22,1,0)) -> 1 | AA9: =IF(ISBLANK(F9),"",IF(F9=Truth!C$22,1,0)) -> 1 | AB9: =IF(ISBLANK(G9),"",IF(G9=Truth!D$22,1,0)) -> 1 | AC9: =IF(ISBLANK(H9),"",IF(H9=Truth!E$22,1,0)) -> 1 | AD9: =IF(ISBLANK(I9),"",IF(I9=Truth!F$22,1,0)) -> 0 | AE9: =IF(ISBLANK(J9),"",IF(J9=Truth!G$22,1,0)) -> 1 | AF9: =IF(ISBLANK(K9),"",IF(K9=Truth!H$22,1,0)) -> 1 | AG9: =IF(ISBLANK(L9),"",IF(L9=Truth!I$22,1,0)) -> 1 | ... AS9: =IF(ISBLANK(X9),"",IF(X9=Truth!U$22,1,0)) -> 0 | AT9: =AVERAGE(Z9:AS9) -> 0.77777778 | AU9: {=SUM(N(LEN(TRIM(Z9:AS9))>0))} -> 18 | AV9: =sum(Z9:AS9) -> 14
A10: P09 | B10: =IF(COUNTIF('Fieldwork W1'!$A$4:$A$22, A10) > 0, "1", IF(COUNTIF('Fieldwork W1'!$A$28:$A$46, A10) > 0, "2", "")) -> 2 | C10: =IF(COUNTIF('Fieldwork W2'!$A$4:$A$22, A10) > 0, "1", IF(COUNTIF('Fieldwork W2'!$A$28:$A$46, A10) > 0, "2", "")) -> 1 | D10: =B10&C10 -> 21 | E10: A | F10: B | G10: B | H10: A | I10: B | K10: A | L10: B | N10: A | O10: A | R10: A | S10: A | T10: B | U10: B | V10: A | W10: B | Y10: =(COUNTIF(E10:X10,"A")+COUNTIF(E10:X10,"B"))/20 -> 0.75 | Z10: =IF(ISBLANK(E10),"",IF(E10=Truth!B$24,1,0)) -> 1 | AA10: =IF(ISBLANK(F10),"",IF(F10=Truth!C$24,1,0)) -> 1 | AB10: =IF(ISBLANK(G10),"",IF(G10=Truth!D$24,1,0)) -> 1 | AC10: =IF(ISBLANK(H10),"",IF(H10=Truth!E$24,1,0)) -> 0 | AD10: =IF(ISBLANK(I10),"",IF(I10=Truth!F$24,1,0)) -> 0 | AE10: =IF(ISBLANK(J10),"",IF(J10=Truth!G$24,1,0)) | AF10: =IF(ISBLANK(K10),"",IF(K10=Truth!H$24,1,0)) -> 0 | AG10: =IF(ISBLANK(L10),"",IF(L10=Truth!I$24,1,0)) -> 1 | ... AS10: =IF(ISBLANK(X10),"",IF(X10=Truth!U$24,1,0)) | AT10: =AVERAGE(Z10:AS10) -> 0.73333333 | AU10: {=SUM(N(LEN(TRIM(Z10:AS10))>0))} -> 15 | AV10: =sum(Z10:AS10) -> 11
A11: P10 | B11: =IF(COUNTIF('Fieldwork W1'!$A$4:$A$22, A11) > 0, "1", IF(COUNTIF('Fieldwork W1'!$A$28:$A$46, A11) > 0, "2", "")) -> 2 | C11: =IF(COUNTIF('Fieldwork W2'!$A$4:$A$22, A11) > 0, "1", IF(COUNTIF('Fieldwork W2'!$A$28:$A$46, A11) > 0, "2", "")) -> 1 | D11: =B11&C11 -> 21 | E11: A | F11: B | G11: A | H11: A | I11: A | J11: A | K11: A | L11: B | M11: A | N11: A | O11: A | P11: A | Q11: B | R11: A | S11: B | T11: B | U11: A | V11: A | W11: A | X11: A | Y11: =(COUNTIF(E11:X11,"A")+COUNTIF(E11:X11,"B"))/20 -> 1 | Z11: =IF(ISBLANK(E11),"",IF(E11=Truth!B$24,1,0)) -> 1 | AA11: =IF(ISBLANK(F11),"",IF(F11=Truth!C$24,1,0)) -> 1 | AB11: =IF(ISBLANK(G11),"",IF(G11=Truth!D$24,1,0)) -> 0 | AC11: =IF(ISBLANK(H11),"",IF(H11=Truth!E$24,1,0)) -> 0 | AD11: =IF(ISBLANK(I11),"",IF(I11=Truth!F$24,1,0)) -> 1 | AE11: =IF(ISBLANK(J11),"",IF(J11=Truth!G$24,1,0)) -> 1 | AF11: =IF(ISBLANK(K11),"",IF(K11=Truth!H$24,1,0)) -> 0 | AG11: =IF(ISBLANK(L11),"",IF(L11=Truth!I$24,1,0)) -> 1 | ... AS11: =IF(ISBLANK(X11),"",IF(X11=Truth!U$24,1,0)) -> 1 | AT11: =AVERAGE(Z11:AS11) -> 0.55 | AU11: {=SUM(N(LEN(TRIM(Z11:AS11))>0))} -> 20 | AV11: =sum(Z11:AS11) -> 11
A12: P11 | B12: =IF(COUNTIF('Fieldwork W1'!$A$4:$A$22, A12) > 0, "1", IF(COUNTIF('Fieldwork W1'!$A$28:$A$46, A12) > 0, "2", "")) -> 1 | C12: =IF(COUNTIF('Fieldwork W2'!$A$4:$A$22, A12) > 0, "1", IF(COUNTIF('Fieldwork W2'!$A$28:$A$46, A12) > 0, "2", "")) -> 1 | D12: =B12&C12 -> 11 | E12: A | F12: A | G12: B | H12: A | I12: A | J12: A | K12: A | L12: B | N12: B | O12: B | P12: A | Q12: A | R12: B | S12: A | T12: B | U12: A | V12: B | W12: A | X12: B | Y12: =(COUNTIF(E12:X12,"A")+COUNTIF(E12:X12,"B"))/20 -> 0.95 | Z12: =IF(ISBLANK(E12),"",IF(E12=Truth!B$22,1,0)) -> 1 | AA12: =IF(ISBLANK(F12),"",IF(F12=Truth!C$22,1,0)) -> 0 | AB12: =IF(ISBLANK(G12),"",IF(G12=Truth!D$22,1,0)) -> 1 | AC12: =IF(ISBLANK(H12),"",IF(H12=Truth!E$22,1,0)) -> 0 | AD12: =IF(ISBLANK(I12),"",IF(I12=Truth!F$22,1,0)) -> 1 | AE12: =IF(ISBLANK(J12),"",IF(J12=Truth!G$22,1,0)) -> 1 | AF12: =IF(ISBLANK(K12),"",IF(K12=Truth!H$22,1,0)) -> 1 | AG12: =IF(ISBLANK(L12),"",IF(L12=Truth!I$22,1,0)) -> 1 | ... AS12: =IF(ISBLANK(X12),"",IF(X12=Truth!U$22,1,0)) -> 0 | AT12: =AVERAGE(Z12:AS12) -> 0.57894737 | AU12: {=SUM(N(LEN(TRIM(Z12:AS12))>0))} -> 19 | AV12: =sum(Z12:AS12) -> 11
A13: P12 | B13: =IF(COUNTIF('Fieldwork W1'!$A$4:$A$22, A13) > 0, "1", IF(COUNTIF('Fieldwork W1'!$A$28:$A$46, A13) > 0, "2", "")) -> 2 | C13: =IF(COUNTIF('Fieldwork W2'!$A$4:$A$22, A13) > 0, "1", IF(COUNTIF('Fieldwork W2'!$A$28:$A$46, A13) > 0, "2", "")) -> 2 | D13: =B13&C13 -> 22 | E13: A | F13: A | G13: A | H13: A | I13: A | J13: B | K13: B | L13: A | M13: B | N13: A | P13: B | Q13: B | R13: A | S13: B | T13: A | U13: A | V13: A | W13: B | X13: A | Y13: =(COUNTIF(E13:X13,"A")+COUNTIF(E13:X13,"B"))/20 -> 0.95 | Z13: =IF(ISBLANK(E13),"",IF(E13=Truth!B$25,1,0)) -> 1 | AA13: =IF(ISBLANK(F13),"",IF(F13=Truth!C$25,1,0)) -> 0 | AB13: =IF(ISBLANK(G13),"",IF(G13=Truth!D$25,1,0)) -> 0 | AC13: =IF(ISBLANK(H13),"",IF(H13=Truth!E$25,1,0)) -> 0 | AD13: =IF(ISBLANK(I13),"",IF(I13=Truth!F$25,1,0)) -> 1 | AE13: =IF(ISBLANK(J13),"",IF(J13=Truth!G$25,1,0)) -> 0 | AF13: =IF(ISBLANK(K13),"",IF(K13=Truth!H$25,1,0)) -> 1 | AG13: =IF(ISBLANK(L13),"",IF(L13=Truth!I$25,1,0)) -> 0 | ... AS13: =IF(ISBLANK(X13),"",IF(X13=Truth!U$25,1,0)) -> 1 | AT13: =AVERAGE(Z13:AS13) -> 0.57894737 | AU13: {=SUM(N(LEN(TRIM(Z13:AS13))>0))} -> 19 | AV13: =sum(Z13:AS13) -> 11
A14: P13 | B14: =IF(COUNTIF('Fieldwork W1'!$A$4:$A$22, A14) > 0, "1", IF(COUNTIF('Fieldwork W1'!$A$28:$A$46, A14) > 0, "2", "")) -> 1 | C14: =IF(COUNTIF('Fieldwork W2'!$A$4:$A$22, A14) > 0, "1", IF(COUNTIF('Fieldwork W2'!$A$28:$A$46, A14) > 0, "2", "")) -> 2 | D14: =B14&C14 -> 12 | E14: A | F14: B | G14: B | H14: B | I14: B | J14: A | K14: A | L14: A | M14: B | N14: A | O14: B | P14: A | Q14: A | R14: A | S14: A | T14: A | U14: A | V14: A | W14: A | X14: A | Y14: =(COUNTIF(E14:X14,"A")+COUNTIF(E14:X14,"B"))/20 -> 1 | Z14: =IF(ISBLANK(E14),"",IF(E14=Truth!B$23,1,0)) -> 1 | AA14: =IF(ISBLANK(F14),"",IF(F14=Truth!C$23,1,0)) -> 1 | AB14: =IF(ISBLANK(G14),"",IF(G14=Truth!D$23,1,0)) -> 1 | AC14: =IF(ISBLANK(H14),"",IF(H14=Truth!E$23,1,0)) -> 1 | AD14: =IF(ISBLANK(I14),"",IF(I14=Truth!F$23,1,0)) -> 0 | AE14: =IF(ISBLANK(J14),"",IF(J14=Truth!G$23,1,0)) -> 1 | AF14: =IF(ISBLANK(K14),"",IF(K14=Truth!H$23,1,0)) -> 1 | AG14: =IF(ISBLANK(L14),"",IF(L14=Truth!I$23,1,0)) -> 0 | ... AS14: =IF(ISBLANK(X14),"",IF(X14=Truth!U$23,1,0)) -> 1 | AT14: =AVERAGE(Z14:AS14) -> 0.6 | AU14: {=SUM(N(LEN(TRIM(Z14:AS14))>0))} -> 20 | AV14: =sum(Z14:AS14) -> 12
A15: P14 | B15: =IF(COUNTIF('Fieldwork W1'!$A$4:$A$22, A15) > 0, "1", IF(COUNTIF('Fieldwork W1'!$A$28:$A$46, A15) > 0, "2", "")) -> 2 | C15: =IF(COUNTIF('Fieldwork W2'!$A$4:$A$22, A15) > 0, "1", IF(COUNTIF('Fieldwork W2'!$A$28:$A$46, A15) > 0, "2", "")) -> 2 | D15: =B15&C15 -> 22 | E15: A | F15: A | G15: B | H15: A | I15: A | J15: A | K15: B | L15: A | M15: A | N15: A | O15: A | P15: B | Q15: A | R15: A | S15: B | T15: B | U15: A | V15: A | W15: B | X15: A | Y15: =(COUNTIF(E15:X15,"A")+COUNTIF(E15:X15,"B"))/20 -> 1 | Z15: =IF(ISBLANK(E15),"",IF(E15=Truth!B$25,1,0)) -> 1 | AA15: =IF(ISBLANK(F15),"",IF(F15=Truth!C$25,1,0)) -> 0 | AB15: =IF(ISBLANK(G15),"",IF(G15=Truth!D$25,1,0)) -> 1 | AC15: =IF(ISBLANK(H15),"",IF(H15=Truth!E$25,1,0)) -> 0 | AD15: =IF(ISBLANK(I15),"",IF(I15=Truth!F$25,1,0)) -> 1 | AE15: =IF(ISBLANK(J15),"",IF(J15=Truth!G$25,1,0)) -> 1 | AF15: =IF(ISBLANK(K15),"",IF(K15=Truth!H$25,1,0)) -> 1 | AG15: =IF(ISBLANK(L15),"",IF(L15=Truth!I$25,1,0)) -> 0 | ... AS15: =IF(ISBLANK(X15),"",IF(X15=Truth!U$25,1,0)) -> 1 | AT15: =AVERAGE(Z15:AS15) -> 0.6 | AU15: {=SUM(N(LEN(TRIM(Z15:AS15))>0))} -> 20 | AV15: =sum(Z15:AS15) -> 12
A16: P15 | B16: =IF(COUNTIF('Fieldwork W1'!$A$4:$A$22, A16) > 0, "1", IF(COUNTIF('Fieldwork W1'!$A$28:$A$46, A16) > 0, "2", "")) -> 1 | C16: =IF(COUNTIF('Fieldwork W2'!$A$4:$A$22, A16) > 0, "1", IF(COUNTIF('Fieldwork W2'!$A$28:$A$46, A16) > 0, "2", "")) -> 2 | D16: =B16&C16 -> 12 | E16: A | F16: B | G16: B | H16: B | I16: A | J16: B | L16: B | M16: B | N16: A | O16: A | P16: A | Q16: B | R16: A | T16: B | U16: A | V16: A | W16: A | X16: A | Y16: =(COUNTIF(E16:X16,"A")+COUNTIF(E16:X16,"B"))/20 -> 0.9 | Z16: =IF(ISBLANK(E16),"",IF(E16=Truth!B$23,1,0)) -> 1 | AA16: =IF(ISBLANK(F16),"",IF(F16=Truth!C$23,1,0)) -> 1 | AB16: =IF(ISBLANK(G16),"",IF(G16=Truth!D$23,1,0)) -> 1 | AC16: =IF(ISBLANK(H16),"",IF(H16=Truth!E$23,1,0)) -> 1 | AD16: =IF(ISBLANK(I16),"",IF(I16=Truth!F$23,1,0)) -> 1 | AE16: =IF(ISBLANK(J16),"",IF(J16=Truth!G$23,1,0)) -> 0 | AF16: =IF(ISBLANK(K16),"",IF(K16=Truth!H$23,1,0)) | AG16: =IF(ISBLANK(L16),"",IF(L16=Truth!I$23,1,0)) -> 1 | ... AS16: =IF(ISBLANK(X16),"",IF(X16=Truth!U$23,1,0)) -> 1 | AT16: =AVERAGE(Z16:AS16) -> 0.61111111 | AU16: {=SUM(N(LEN(TRIM(Z16:AS16))>0))} -> 18 | AV16: =sum(Z16:AS16) -> 11
A17: P16 | B17: =IF(COUNTIF('Fieldwork W1'!$A$4:$A$22, A17) > 0, "1", IF(COUNTIF('Fieldwork W1'!$A$28:$A$46, A17) > 0, "2", "")) -> 2 | C17: =IF(COUNTIF('Fieldwork W2'!$A$4:$A$22, A17) > 0, "1", IF(COUNTIF('Fieldwork W2'!$A$28:$A$46, A17) > 0, "2", "")) -> 2 | D17: =B17&C17 -> 22 | E17: A | F17: B | G17: B | H17: A | I17: B | J17: A | K17: A | L17: A | M17: A | N17: A | O17: A | P17: A | Q17: A | R17: A | S17: B | U17: B | V17: A | W17: A | X17: A | Y17: =(COUNTIF(E17:X17,"A")+COUNTIF(E17:X17,"B"))/20 -> 0.95 | Z17: =IF(ISBLANK(E17),"",IF(E17=Truth!B$25,1,0)) -> 1 | AA17: =IF(ISBLANK(F17),"",IF(F17=Truth!C$25,1,0)) -> 1 | AB17: =IF(ISBLANK(G17),"",IF(G17=Truth!D$25,1,0)) -> 1 | AC17: =IF(ISBLANK(H17),"",IF(H17=Truth!E$25,1,0)) -> 0 | AD17: =IF(ISBLANK(I17),"",IF(I17=Truth!F$25,1,0)) -> 0 | AE17: =IF(ISBLANK(J17),"",IF(J17=Truth!G$25,1,0)) -> 1 | AF17: =IF(ISBLANK(K17),"",IF(K17=Truth!H$25,1,0)) -> 0 | AG17: =IF(ISBLANK(L17),"",IF(L17=Truth!I$25,1,0)) -> 0 | ... AS17: =IF(ISBLANK(X17),"",IF(X17=Truth!U$25,1,0)) -> 1 | AT17: =AVERAGE(Z17:AS17) -> 0.63157895 | AU17: {=SUM(N(LEN(TRIM(Z17:AS17))>0))} -> 19 | AV17: =sum(Z17:AS17) -> 12
A18: P17 | B18: =IF(COUNTIF('Fieldwork W1'!$A$4:$A$22, A18) > 0, "1", IF(COUNTIF('Fieldwork W1'!$A$28:$A$46, A18) > 0, "2", "")) -> 1 | C18: =IF(COUNTIF('Fieldwork W2'!$A$4:$A$22, A18) > 0, "1", IF(COUNTIF('Fieldwork W2'!$A$28:$A$46, A18) > 0, "2", "")) -> 2 | D18: =B18&C18 -> 12 | F18: A | G18: B | H18: A | I18: A | J18: A | K18: A | L18: B | M18: A | N18: A | Y18: =(COUNTIF(E18:X18,"A")+COUNTIF(E18:X18,"B"))/20 -> 0.45 | Z18: =IF(ISBLANK(E18),"",IF(E18=Truth!B$22,1,0)) | AA18: =IF(ISBLANK(F18),"",IF(F18=Truth!C$22,1,0)) -> 0 | AB18: =IF(ISBLANK(G18),"",IF(G18=Truth!D$22,1,0)) -> 1 | AC18: =IF(ISBLANK(H18),"",IF(H18=Truth!E$22,1,0)) -> 0 | AD18: =IF(ISBLANK(I18),"",IF(I18=Truth!F$22,1,0)) -> 1 | AE18: =IF(ISBLANK(J18),"",IF(J18=Truth!G$22,1,0)) -> 1 | AF18: =IF(ISBLANK(K18),"",IF(K18=Truth!H$22,1,0)) -> 1 | AG18: =IF(ISBLANK(L18),"",IF(L18=Truth!I$22,1,0)) -> 1 | ... AS18: =IF(ISBLANK(X18),"",IF(X18=Truth!U$22,1,0)) | AT18: =AVERAGE(Z18:AS18) -> 0.66666667 | AU18: {=SUM(N(LEN(TRIM(Z18:AS18))>0))} -> 9 | AV18: =sum(Z18:AS18) -> 6
A19: P18 | B19: =IF(COUNTIF('Fieldwork W1'!$A$4:$A$22, A19) > 0, "1", IF(COUNTIF('Fieldwork W1'!$A$28:$A$46, A19) > 0, "2", "")) -> 2 | C19: =IF(COUNTIF('Fieldwork W2'!$A$4:$A$22, A19) > 0, "1", IF(COUNTIF('Fieldwork W2'!$A$28:$A$46, A19) > 0, "2", "")) -> 2 | D19: =B19&C19 -> 22 | L19: A | M19: A | N19: B | O19: B | P19: A | Q19: A | S19: A | T19: A | U19: B | V19: A | W19: A | X19: A | Y19: =(COUNTIF(E19:X19,"A")+COUNTIF(E19:X19,"B"))/20 -> 0.6 | Z19: =IF(ISBLANK(E19),"",IF(E19=Truth!B$23,1,0)) | AA19: =IF(ISBLANK(F19),"",IF(F19=Truth!C$23,1,0)) | AB19: =IF(ISBLANK(G19),"",IF(G19=Truth!D$23,1,0)) | AC19: =IF(ISBLANK(H19),"",IF(H19=Truth!E$23,1,0)) | AD19: =IF(ISBLANK(I19),"",IF(I19=Truth!F$23,1,0)) | AE19: =IF(ISBLANK(J19),"",IF(J19=Truth!G$23,1,0)) | AF19: =IF(ISBLANK(K19),"",IF(K19=Truth!H$23,1,0)) | AG19: =IF(ISBLANK(L19),"",IF(L19=Truth!I$23,1,0)) -> 0 | ... AS19: =IF(ISBLANK(X19),"",IF(X19=Truth!U$23,1,0)) -> 1 | AT19: =AVERAGE(Z19:AS19) -> 0.66666667 | AU19: {=SUM(N(LEN(TRIM(Z19:AS19))>0))} -> 12 | AV19: =sum(Z19:AS19) -> 8
A20: P19 | B20: =IF(COUNTIF('Fieldwork W1'!$A$4:$A$22, A20) > 0, "1", IF(COUNTIF('Fieldwork W1'!$A$28:$A$46, A20) > 0, "2", "")) -> 1 | C20: =IF(COUNTIF('Fieldwork W2'!$A$4:$A$22, A20) > 0, "1", IF(COUNTIF('Fieldwork W2'!$A$28:$A$46, A20) > 0, "2", "")) -> 2 | D20: =B20&C20 -> 12 | G20: B | H20: B | I20: A | J20: A | K20: B | L20: A | M20: A | N20: A | O20: A | P20: A | Q20: A | R20: A | S20: A | T20: A | U20: A | V20: A | W20: A | X20: A | Y20: =(COUNTIF(E20:X20,"A")+COUNTIF(E20:X20,"B"))/20 -> 0.9 | Z20: =IF(ISBLANK(E20),"",IF(E20=Truth!B$25,1,0)) | AA20: =IF(ISBLANK(F20),"",IF(F20=Truth!C$25,1,0)) | AB20: =IF(ISBLANK(G20),"",IF(G20=Truth!D$25,1,0)) -> 1 | AC20: =IF(ISBLANK(H20),"",IF(H20=Truth!E$25,1,0)) -> 1 | AD20: =IF(ISBLANK(I20),"",IF(I20=Truth!F$25,1,0)) -> 1 | AE20: =IF(ISBLANK(J20),"",IF(J20=Truth!G$25,1,0)) -> 1 | AF20: =IF(ISBLANK(K20),"",IF(K20=Truth!H$25,1,0)) -> 1 | AG20: =IF(ISBLANK(L20),"",IF(L20=Truth!I$25,1,0)) -> 0 | ... AS20: =IF(ISBLANK(X20),"",IF(X20=Truth!U$25,1,0)) -> 1 | AT20: =AVERAGE(Z20:AS20) -> 0.66666667 | AU20: {=SUM(N(LEN(TRIM(Z20:AS20))>0))} -> 18 | AV20: =sum(Z20:AS20) -> 12
A21: P20 | B21: =IF(COUNTIF('Fieldwork W1'!$A$4:$A$22, A21) > 0, "1", IF(COUNTIF('Fieldwork W1'!$A$28:$A$46, A21) > 0, "2", "")) -> 1 | C21: =IF(COUNTIF('Fieldwork W2'!$A$4:$A$22, A21) > 0, "1", IF(COUNTIF('Fieldwork W2'!$A$28:$A$46, A21) > 0, "2", "")) -> 2 | D21: =B21&C21 -> 12 | E21: B | F21: A | G21: B | H21: A | I21: A | J21: B | K21: B | L21: A | M21: A | N21: A | O21: A | P21: A | Q21: A | R21: A | T21: B | U21: A | V21: A | W21: A | X21: A | Y21: =(COUNTIF(E21:X21,"A")+COUNTIF(E21:X21,"B"))/20 -> 0.95 | Z21: =IF(ISBLANK(E21),"",IF(E21=Truth!B$23,1,0)) -> 0 | AA21: =IF(ISBLANK(F21),"",IF(F21=Truth!C$23,1,0)) -> 0 | AB21: =IF(ISBLANK(G21),"",IF(G21=Truth!D$23,1,0)) -> 1 | AC21: =IF(ISBLANK(H21),"",IF(H21=Truth!E$23,1,0)) -> 0 | AD21: =IF(ISBLANK(I21),"",IF(I21=Truth!F$23,1,0)) -> 1 | AE21: =IF(ISBLANK(J21),"",IF(J21=Truth!G$23,1,0)) -> 0 | AF21: =IF(ISBLANK(K21),"",IF(K21=Truth!H$23,1,0)) -> 0 | AG21: =IF(ISBLANK(L21),"",IF(L21=Truth!I$23,1,0)) -> 0 | ... AS21: =IF(ISBLANK(X21),"",IF(X21=Truth!U$23,1,0)) -> 1 | AT21: =AVERAGE(Z21:AS21) -> 0.36842105 | AU21: {=SUM(N(LEN(TRIM(Z21:AS21))>0))} -> 19 | AV21: =sum(Z21:AS21) -> 7
A22: P21 | B22: =IF(COUNTIF('Fieldwork W1'!$A$4:$A$22, A22) > 0, "1", IF(COUNTIF('Fieldwork W1'!$A$28:$A$46, A22) > 0, "2", "")) -> 1 | C22: =IF(COUNTIF('Fieldwork W2'!$A$4:$A$22, A22) > 0, "1", IF(COUNTIF('Fieldwork W2'!$A$28:$A$46, A22) > 0, "2", "")) -> 1 | D22: =B22&C22 -> 11 | K22: A | L22: B | M22: B | N22: A | O22: A | P22: B | Q22: A | R22: A | S22: B | T22: A | U22: A | V22: A | W22: A | X22: A | Y22: =(COUNTIF(E22:X22,"A")+COUNTIF(E22:X22,"B"))/20 -> 0.7 | Z22: =IF(ISBLANK(E22),"",IF(E22=Truth!B$23,1,0)) | AA22: =IF(ISBLANK(F22),"",IF(F22=Truth!C$23,1,0)) | AB22: =IF(ISBLANK(G22),"",IF(G22=Truth!D$23,1,0)) | AC22: =IF(ISBLANK(H22),"",IF(H22=Truth!E$23,1,0)) | AD22: =IF(ISBLANK(I22),"",IF(I22=Truth!F$23,1,0)) | AE22: =IF(ISBLANK(J22),"",IF(J22=Truth!G$23,1,0)) | AF22: =IF(ISBLANK(K22),"",IF(K22=Truth!H$23,1,0)) -> 1 | AG22: =IF(ISBLANK(L22),"",IF(L22=Truth!I$23,1,0)) -> 1 | ... AS22: =IF(ISBLANK(X22),"",IF(X22=Truth!U$23,1,0)) -> 1 | AT22: =AVERAGE(Z22:AS22) -> 0.5 | AU22: {=SUM(N(LEN(TRIM(Z22:AS22))>0))} -> 14 | AV22: =sum(Z22:AS22) -> 7
A23: P22 | B23: =IF(COUNTIF('Fieldwork W1'!$A$4:$A$22, A23) > 0, "1", IF(COUNTIF('Fieldwork W1'!$A$28:$A$46, A23) > 0, "2", "")) -> 2 | C23: =IF(COUNTIF('Fieldwork W2'!$A$4:$A$22, A23) > 0, "1", IF(COUNTIF('Fieldwork W2'!$A$28:$A$46, A23) > 0, "2", "")) -> 1 | D23: =B23&C23 -> 21 | I23: A | J23: A | K23: A | L23: A | M23: A | N23: A | O23: B | P23: A | Q23: A | R23: B | S23: A | T23: A | U23: A | V23: A | W23: A | X23: B | Y23: =(COUNTIF(E23:X23,"A")+COUNTIF(E23:X23,"B"))/20 -> 0.8 | Z23: =IF(ISBLANK(E23),"",IF(E23=Truth!B$22,1,0)) | AA23: =IF(ISBLANK(F23),"",IF(F23=Truth!C$22,1,0)) | AB23: =IF(ISBLANK(G23),"",IF(G23=Truth!D$22,1,0)) | AC23: =IF(ISBLANK(H23),"",IF(H23=Truth!E$22,1,0)) | AD23: =IF(ISBLANK(I23),"",IF(I23=Truth!F$22,1,0)) -> 1 | AE23: =IF(ISBLANK(J23),"",IF(J23=Truth!G$22,1,0)) -> 1 | AF23: =IF(ISBLANK(K23),"",IF(K23=Truth!H$22,1,0)) -> 1 | AG23: =IF(ISBLANK(L23),"",IF(L23=Truth!I$22,1,0)) -> 0 | ... AS23: =IF(ISBLANK(X23),"",IF(X23=Truth!U$22,1,0)) -> 0 | AT23: =AVERAGE(Z23:AS23) -> 0.5 | AU23: {=SUM(N(LEN(TRIM(Z23:AS23))>0))} -> 16 | AV23: =sum(Z23:AS23) -> 8
A24: P23 | B24: =IF(COUNTIF('Fieldwork W1'!$A$4:$A$22, A24) > 0, "1", IF(COUNTIF('Fieldwork W1'!$A$28:$A$46, A24) > 0, "2", "")) -> 2 | C24: =IF(COUNTIF('Fieldwork W2'!$A$4:$A$22, A24) > 0, "1", IF(COUNTIF('Fieldwork W2'!$A$28:$A$46, A24) > 0, "2", "")) -> 2 | D24: =B24&C24 -> 22 | E24: A | F24: B | G24: A | H24: B | I24: A | J24: A | K24: B | M24: A | N24: A | P24: A | Q24: B | R24: B | S24: A | T24: B | U24: A | V24: A | W24: A | X24: A | Y24: =(COUNTIF(E24:X24,"A")+COUNTIF(E24:X24,"B"))/20 -> 0.9 | Z24: =IF(ISBLANK(E24),"",IF(E24=Truth!B$24,1,0)) -> 1 | AA24: =IF(ISBLANK(F24),"",IF(F24=Truth!C$24,1,0)) -> 1 | AB24: =IF(ISBLANK(G24),"",IF(G24=Truth!D$24,1,0)) -> 0 | AC24: =IF(ISBLANK(H24),"",IF(H24=Truth!E$24,1,0)) -> 1 | AD24: =IF(ISBLANK(I24),"",IF(I24=Truth!F$24,1,0)) -> 1 | AE24: =IF(ISBLANK(J24),"",IF(J24=Truth!G$24,1,0)) -> 1 | AF24: =IF(ISBLANK(K24),"",IF(K24=Truth!H$24,1,0)) -> 1 | AG24: =IF(ISBLANK(L24),"",IF(L24=Truth!I$24,1,0)) | ... AS24: =IF(ISBLANK(X24),"",IF(X24=Truth!U$24,1,0)) -> 1 | AT24: =AVERAGE(Z24:AS24) -> 0.72222222 | AU24: {=SUM(N(LEN(TRIM(Z24:AS24))>0))} -> 18 | AV24: =sum(Z24:AS24) -> 13
A25: P24 | B25: =IF(COUNTIF('Fieldwork W1'!$A$4:$A$22, A25) > 0, "1", IF(COUNTIF('Fieldwork W1'!$A$28:$A$46, A25) > 0, "2", "")) -> 1 | C25: =IF(COUNTIF('Fieldwork W2'!$A$4:$A$22, A25) > 0, "1", IF(COUNTIF('Fieldwork W2'!$A$28:$A$46, A25) > 0, "2", "")) -> 1 | D25: =B25&C25 -> 11 | E25: A | F25: B | G25: B | H25: A | I25: B | J25: A | K25: A | L25: A | M25: A | N25: A | O25: ______ | W25: A | X25: A | Y25: =(COUNTIF(E25:X25,"A")+COUNTIF(E25:X25,"B"))/20 -> 0.6 | Z25: =IF(ISBLANK(E25),"",IF(E25=Truth!B$25,1,0)) -> 1 | AA25: =IF(ISBLANK(F25),"",IF(F25=Truth!C$25,1,0)) -> 1 | AB25: =IF(ISBLANK(G25),"",IF(G25=Truth!D$25,1,0)) -> 1 | AC25: =IF(ISBLANK(H25),"",IF(H25=Truth!E$25,1,0)) -> 0 | AD25: =IF(ISBLANK(I25),"",IF(I25=Truth!F$25,1,0)) -> 0 | AE25: =IF(ISBLANK(J25),"",IF(J25=Truth!G$25,1,0)) -> 1 | AF25: =IF(ISBLANK(K25),"",IF(K25=Truth!H$25,1,0)) -> 0 | AG25: =IF(ISBLANK(L25),"",IF(L25=Truth!I$25,1,0)) -> 0 | ... AS25: =IF(ISBLANK(X25),"",IF(X25=Truth!U$25,1,0)) -> 1 | AT25: =AVERAGE(Z25:AS25) -> 0.53846154 | AU25: {=SUM(N(LEN(TRIM(Z25:AS25))>0))} -> 13 | AV25: =sum(Z25:AS25) -> 7
A26: P25 | B26: =IF(COUNTIF('Fieldwork W1'!$A$4:$A$22, A26) > 0, "1", IF(COUNTIF('Fieldwork W1'!$A$28:$A$46, A26) > 0, "2", "")) -> 2 | C26: =IF(COUNTIF('Fieldwork W2'!$A$4:$A$22, A26) > 0, "1", IF(COUNTIF('Fieldwork W2'!$A$28:$A$46, A26) > 0, "2", "")) -> 2 | D26: =B26&C26 -> 22 | E26: B | F26: B | G26: B | I26: A | J26: A | K26: A | L26: B | M26: A | N26: B | O26: A | P26: B | Q26: B | R26: A | S26: A | T26: B | U26: B | V26: A | W26: A | X26: B | Y26: =(COUNTIF(E26:X26,"A")+COUNTIF(E26:X26,"B"))/20 -> 0.95 | Z26: =IF(ISBLANK(E26),"",IF(E26=Truth!B$22,1,0)) -> 0 | AA26: =IF(ISBLANK(F26),"",IF(F26=Truth!C$22,1,0)) -> 1 | AB26: =IF(ISBLANK(G26),"",IF(G26=Truth!D$22,1,0)) -> 1 | AC26: =IF(ISBLANK(H26),"",IF(H26=Truth!E$22,1,0)) | AD26: =IF(ISBLANK(I26),"",IF(I26=Truth!F$22,1,0)) -> 1 | AE26: =IF(ISBLANK(J26),"",IF(J26=Truth!G$22,1,0)) -> 1 | AF26: =IF(ISBLANK(K26),"",IF(K26=Truth!H$22,1,0)) -> 1 | AG26: =IF(ISBLANK(L26),"",IF(L26=Truth!I$22,1,0)) -> 1 | ... AS26: =IF(ISBLANK(X26),"",IF(X26=Truth!U$22,1,0)) -> 0 | AT26: =AVERAGE(Z26:AS26) -> 0.73684211 | AU26: {=SUM(N(LEN(TRIM(Z26:AS26))>0))} -> 19 | AV26: =sum(Z26:AS26) -> 14
A27: P26 | B27: =IF(COUNTIF('Fieldwork W1'!$A$4:$A$22, A27) > 0, "1", IF(COUNTIF('Fieldwork W1'!$A$28:$A$46, A27) > 0, "2", "")) -> 2 | C27: =IF(COUNTIF('Fieldwork W2'!$A$4:$A$22, A27) > 0, "1", IF(COUNTIF('Fieldwork W2'!$A$28:$A$46, A27) > 0, "2", "")) -> 1 | D27: =B27&C27 -> 21 | E27: A | F27: B | G27: A | H27: B | I27: A | J27: A | K27: B | L27: A | M27: A | N27: A | O27: A | P27: B | Q27: B | R27: A | S27: B | U27: A | V27: A | W27: B | X27: A | Y27: =(COUNTIF(E27:X27,"A")+COUNTIF(E27:X27,"B"))/20 -> 0.95 | Z27: =IF(ISBLANK(E27),"",IF(E27=Truth!B$25,1,0)) -> 1 | AA27: =IF(ISBLANK(F27),"",IF(F27=Truth!C$25,1,0)) -> 1 | AB27: =IF(ISBLANK(G27),"",IF(G27=Truth!D$25,1,0)) -> 0 | AC27: =IF(ISBLANK(H27),"",IF(H27=Truth!E$25,1,0)) -> 1 | AD27: =IF(ISBLANK(I27),"",IF(I27=Truth!F$25,1,0)) -> 1 | AE27: =IF(ISBLANK(J27),"",IF(J27=Truth!G$25,1,0)) -> 1 | AF27: =IF(ISBLANK(K27),"",IF(K27=Truth!H$25,1,0)) -> 1 | AG27: =IF(ISBLANK(L27),"",IF(L27=Truth!I$25,1,0)) -> 0 | ... AS27: =IF(ISBLANK(X27),"",IF(X27=Truth!U$25,1,0)) -> 1 | AT27: =AVERAGE(Z27:AS27) -> 0.73684211 | AU27: {=SUM(N(LEN(TRIM(Z27:AS27))>0))} -> 19 | AV27: =sum(Z27:AS27) -> 14
A28: P27 | B28: =IF(COUNTIF('Fieldwork W1'!$A$4:$A$22, A28) > 0, "1", IF(COUNTIF('Fieldwork W1'!$A$28:$A$46, A28) > 0, "2", "")) -> 2 | C28: =IF(COUNTIF('Fieldwork W2'!$A$4:$A$22, A28) > 0, "1", IF(COUNTIF('Fieldwork W2'!$A$28:$A$46, A28) > 0, "2", "")) -> 1 | D28: =B28&C28 -> 21 | E28: A | F28: B | G28: A | H28: A | I28: B | J28: A | K28: B | L28: B | M28: A | N28: A | O28: A | P28: B | Q28: A | R28: A | S28: A | T28: B | U28: B | V28: A | W28: A | X28: A | Y28: =(COUNTIF(E28:X28,"A")+COUNTIF(E28:X28,"B"))/20 -> 1 | Z28: =IF(ISBLANK(E28),"",IF(E28=Truth!B$24,1,0)) -> 1 | AA28: =IF(ISBLANK(F28),"",IF(F28=Truth!C$24,1,0)) -> 1 | AB28: =IF(ISBLANK(G28),"",IF(G28=Truth!D$24,1,0)) -> 0 | AC28: =IF(ISBLANK(H28),"",IF(H28=Truth!E$24,1,0)) -> 0 | AD28: =IF(ISBLANK(I28),"",IF(I28=Truth!F$24,1,0)) -> 0 | AE28: =IF(ISBLANK(J28),"",IF(J28=Truth!G$24,1,0)) -> 1 | AF28: =IF(ISBLANK(K28),"",IF(K28=Truth!H$24,1,0)) -> 1 | AG28: =IF(ISBLANK(L28),"",IF(L28=Truth!I$24,1,0)) -> 1 | ... AS28: =IF(ISBLANK(X28),"",IF(X28=Truth!U$24,1,0)) -> 1 | AT28: =AVERAGE(Z28:AS28) -> 0.75 | AU28: {=SUM(N(LEN(TRIM(Z28:AS28))>0))} -> 20 | AV28: =sum(Z28:AS28) -> 15
A29: P28 | B29: =IF(COUNTIF('Fieldwork W1'!$A$4:$A$22, A29) > 0, "1", IF(COUNTIF('Fieldwork W1'!$A$28:$A$46, A29) > 0, "2", "")) -> 2 | C29: =IF(COUNTIF('Fieldwork W2'!$A$4:$A$22, A29) > 0, "1", IF(COUNTIF('Fieldwork W2'!$A$28:$A$46, A29) > 0, "2", "")) -> 1 | D29: =B29&C29 -> 21 | E29: A | F29: B | G29: B | H29: A | I29: B | J29: B | K29: B | L29: B | M29: A | N29: A | O29: B | P29: B | Q29: A | R29: B | S29: A | T29: B | U29: B | V29: A | W29: A | X29: A | Y29: =(COUNTIF(E29:X29,"A")+COUNTIF(E29:X29,"B"))/20 -> 1 | Z29: =IF(ISBLANK(E29),"",IF(E29=Truth!B$24,1,0)) -> 1 | AA29: =IF(ISBLANK(F29),"",IF(F29=Truth!C$24,1,0)) -> 1 | AB29: =IF(ISBLANK(G29),"",IF(G29=Truth!D$24,1,0)) -> 1 | AC29: =IF(ISBLANK(H29),"",IF(H29=Truth!E$24,1,0)) -> 0 | AD29: =IF(ISBLANK(I29),"",IF(I29=Truth!F$24,1,0)) -> 0 | AE29: =IF(ISBLANK(J29),"",IF(J29=Truth!G$24,1,0)) -> 0 | AF29: =IF(ISBLANK(K29),"",IF(K29=Truth!H$24,1,0)) -> 1 | AG29: =IF(ISBLANK(L29),"",IF(L29=Truth!I$24,1,0)) -> 1 | ... AS29: =IF(ISBLANK(X29),"",IF(X29=Truth!U$24,1,0)) -> 1 | AT29: =AVERAGE(Z29:AS29) -> 0.75 | AU29: {=SUM(N(LEN(TRIM(Z29:AS29))>0))} -> 20 | AV29: =sum(Z29:AS29) -> 15
A30: P29 | B30: =IF(COUNTIF('Fieldwork W1'!$A$4:$A$22, A30) > 0, "1", IF(COUNTIF('Fieldwork W1'!$A$28:$A$46, A30) > 0, "2", "")) -> 1 | C30: =IF(COUNTIF('Fieldwork W2'!$A$4:$A$22, A30) > 0, "1", IF(COUNTIF('Fieldwork W2'!$A$28:$A$46, A30) > 0, "2", "")) -> 2 | D30: =B30&C30 -> 12 | L30: A | M30: A | N30: B | O30: A | P30: B | Q30: B | R30: A | S30: A | T30: B | U30: B | V30: A | W30: A | X30: B | Y30: =(COUNTIF(E30:X30,"A")+COUNTIF(E30:X30,"B"))/20 -> 0.65 | Z30: =IF(ISBLANK(E30),"",IF(E30=Truth!B$24,1,0)) | AA30: =IF(ISBLANK(F30),"",IF(F30=Truth!C$24,1,0)) | AB30: =IF(ISBLANK(G30),"",IF(G30=Truth!D$24,1,0)) | AC30: =IF(ISBLANK(H30),"",IF(H30=Truth!E$24,1,0)) | AD30: =IF(ISBLANK(I30),"",IF(I30=Truth!F$24,1,0)) | AE30: =IF(ISBLANK(J30),"",IF(J30=Truth!G$24,1,0)) | AF30: =IF(ISBLANK(K30),"",IF(K30=Truth!H$24,1,0)) | AG30: =IF(ISBLANK(L30),"",IF(L30=Truth!I$24,1,0)) -> 0 | ... AS30: =IF(ISBLANK(X30),"",IF(X30=Truth!U$24,1,0)) -> 0 | AT30: =AVERAGE(Z30:AS30) -> 0.53846154 | AU30: {=SUM(N(LEN(TRIM(Z30:AS30))>0))} -> 13 | AV30: =sum(Z30:AS30) -> 7
A31: P30 | B31: =IF(COUNTIF('Fieldwork W1'!$A$4:$A$22, A31) > 0, "1", IF(COUNTIF('Fieldwork W1'!$A$28:$A$46, A31) > 0, "2", "")) -> 2 | C31: =IF(COUNTIF('Fieldwork W2'!$A$4:$A$22, A31) > 0, "1", IF(COUNTIF('Fieldwork W2'!$A$28:$A$46, A31) > 0, "2", "")) -> 1 | D31: =B31&C31 -> 21 | E31: A | F31: B | H31: B | I31: A | J31: A | K31: A | L31: B | M31: B | N31: B | O31: A | P31: B | Q31: B | R31: A | S31: B | T31: B | U31: B | V31: A | W31: B | Y31: =(COUNTIF(E31:X31,"A")+COUNTIF(E31:X31,"B"))/20 -> 0.9 | Z31: =IF(ISBLANK(E31),"",IF(E31=Truth!B$23,1,0)) -> 1 | AA31: =IF(ISBLANK(F31),"",IF(F31=Truth!C$23,1,0)) -> 1 | AB31: =IF(ISBLANK(G31),"",IF(G31=Truth!D$23,1,0)) | AC31: =IF(ISBLANK(H31),"",IF(H31=Truth!E$23,1,0)) -> 1 | AD31: =IF(ISBLANK(I31),"",IF(I31=Truth!F$23,1,0)) -> 1 | AE31: =IF(ISBLANK(J31),"",IF(J31=Truth!G$23,1,0)) -> 1 | AF31: =IF(ISBLANK(K31),"",IF(K31=Truth!H$23,1,0)) -> 1 | AG31: =IF(ISBLANK(L31),"",IF(L31=Truth!I$23,1,0)) -> 1 | ... AS31: =IF(ISBLANK(X31),"",IF(X31=Truth!U$23,1,0)) | AT31: =AVERAGE(Z31:AS31) -> 0.77777778 | AU31: {=SUM(N(LEN(TRIM(Z31:AS31))>0))} -> 18 | AV31: =sum(Z31:AS31) -> 14
A32: P31 | B32: =IF(COUNTIF('Fieldwork W1'!$A$4:$A$22, A32) > 0, "1", IF(COUNTIF('Fieldwork W1'!$A$28:$A$46, A32) > 0, "2", "")) -> 2 | C32: =IF(COUNTIF('Fieldwork W2'!$A$4:$A$22, A32) > 0, "1", IF(COUNTIF('Fieldwork W2'!$A$28:$A$46, A32) > 0, "2", "")) -> 1 | D32: =B32&C32 -> 21 | E32: A | F32: B | G32: B | H32: B | I32: A | J32: A | K32: B | L32: A | M32: A | N32: A | O32: A | P32: A | Q32: A | R32: B | S32: A | T32: A | U32: B | V32: A | W32: A | Y32: =(COUNTIF(E32:X32,"A")+COUNTIF(E32:X32,"B"))/20 -> 0.95 | Z32: =IF(ISBLANK(E32),"",IF(E32=Truth!B$24,1,0)) -> 1 | AA32: =IF(ISBLANK(F32),"",IF(F32=Truth!C$24,1,0)) -> 1 | AB32: =IF(ISBLANK(G32),"",IF(G32=Truth!D$24,1,0)) -> 1 | AC32: =IF(ISBLANK(H32),"",IF(H32=Truth!E$24,1,0)) -> 1 | AD32: =IF(ISBLANK(I32),"",IF(I32=Truth!F$24,1,0)) -> 1 | AE32: =IF(ISBLANK(J32),"",IF(J32=Truth!G$24,1,0)) -> 1 | AF32: =IF(ISBLANK(K32),"",IF(K32=Truth!H$24,1,0)) -> 1 | AG32: =IF(ISBLANK(L32),"",IF(L32=Truth!I$24,1,0)) -> 0 | ... AS32: =IF(ISBLANK(X32),"",IF(X32=Truth!U$24,1,0)) | AT32: =AVERAGE(Z32:AS32) -> 0.78947368 | AU32: {=SUM(N(LEN(TRIM(Z32:AS32))>0))} -> 19 | AV32: =sum(Z32:AS32) -> 15
A33: P32 | B33: =IF(COUNTIF('Fieldwork W1'!$A$4:$A$22, A33) > 0, "1", IF(COUNTIF('Fieldwork W1'!$A$28:$A$46, A33) > 0, "2", "")) -> 1 | C33: =IF(COUNTIF('Fieldwork W2'!$A$4:$A$22, A33) > 0, "1", IF(COUNTIF('Fieldwork W2'!$A$28:$A$46, A33) > 0, "2", "")) -> 2 | D33: =B33&C33 -> 12 | E33: A | F33: B | G33: B | H33: A | I33: B | J33: A | K33: B | L33: A | M33: B | N33: A | O33: A | P33: B | Q33: A | S33: A | T33: B | U33: B | V33: A | W33: B | X33: A | Y33: =(COUNTIF(E33:X33,"A")+COUNTIF(E33:X33,"B"))/20 -> 0.95 | Z33: =IF(ISBLANK(E33),"",IF(E33=Truth!B$24,1,0)) -> 1 | AA33: =IF(ISBLANK(F33),"",IF(F33=Truth!C$24,1,0)) -> 1 | AB33: =IF(ISBLANK(G33),"",IF(G33=Truth!D$24,1,0)) -> 1 | AC33: =IF(ISBLANK(H33),"",IF(H33=Truth!E$24,1,0)) -> 0 | AD33: =IF(ISBLANK(I33),"",IF(I33=Truth!F$24,1,0)) -> 0 | AE33: =IF(ISBLANK(J33),"",IF(J33=Truth!G$24,1,0)) -> 1 | AF33: =IF(ISBLANK(K33),"",IF(K33=Truth!H$24,1,0)) -> 1 | AG33: =IF(ISBLANK(L33),"",IF(L33=Truth!I$24,1,0)) -> 0 | ... AS33: =IF(ISBLANK(X33),"",IF(X33=Truth!U$24,1,0)) -> 1 | AT33: =AVERAGE(Z33:AS33) -> 0.78947368 | AU33: {=SUM(N(LEN(TRIM(Z33:AS33))>0))} -> 19 | AV33: =sum(Z33:AS33) -> 15
A34: P33 | B34: =IF(COUNTIF('Fieldwork W1'!$A$4:$A$22, A34) > 0, "1", IF(COUNTIF('Fieldwork W1'!$A$28:$A$46, A34) > 0, "2", "")) -> 2 | C34: =IF(COUNTIF('Fieldwork W2'!$A$4:$A$22, A34) > 0, "1", IF(COUNTIF('Fieldwork W2'!$A$28:$A$46, A34) > 0, "2", "")) -> 1 | D34: =B34&C34 -> 21 | E34: A | F34: B | G34: A | H34: B | I34: A | J34: A | K34: A | L34: B | M34: B | N34: B | O34: A | P34: B | Q34: B | R34: A | T34: A | U34: B | V34: A | W34: B | X34: A | Y34: =(COUNTIF(E34:X34,"A")+COUNTIF(E34:X34,"B"))/20 -> 0.95 | Z34: =IF(ISBLANK(E34),"",IF(E34=Truth!B$23,1,0)) -> 1 | AA34: =IF(ISBLANK(F34),"",IF(F34=Truth!C$23,1,0)) -> 1 | AB34: =IF(ISBLANK(G34),"",IF(G34=Truth!D$23,1,0)) -> 0 | AC34: =IF(ISBLANK(H34),"",IF(H34=Truth!E$23,1,0)) -> 1 | AD34: =IF(ISBLANK(I34),"",IF(I34=Truth!F$23,1,0)) -> 1 | AE34: =IF(ISBLANK(J34),"",IF(J34=Truth!G$23,1,0)) -> 1 | AF34: =IF(ISBLANK(K34),"",IF(K34=Truth!H$23,1,0)) -> 1 | AG34: =IF(ISBLANK(L34),"",IF(L34=Truth!I$23,1,0)) -> 1 | ... AS34: =IF(ISBLANK(X34),"",IF(X34=Truth!U$23,1,0)) -> 1 | AT34: =AVERAGE(Z34:AS34) -> 0.78947368 | AU34: {=SUM(N(LEN(TRIM(Z34:AS34))>0))} -> 19 | AV34: =sum(Z34:AS34) -> 15
A35: P34 | B35: =IF(COUNTIF('Fieldwork W1'!$A$4:$A$22, A35) > 0, "1", IF(COUNTIF('Fieldwork W1'!$A$28:$A$46, A35) > 0, "2", "")) -> 1 | C35: =IF(COUNTIF('Fieldwork W2'!$A$4:$A$22, A35) > 0, "1", IF(COUNTIF('Fieldwork W2'!$A$28:$A$46, A35) > 0, "2", "")) -> 1 | D35: =B35&C35 -> 11 | E35: A | F35: B | G35: B | H35: A | I35: A | J35: A | K35: B | L35: B | M35: A | N35: A | O35: A | P35: A | Q35: A | R35: B | S35: A | T35: B | U35: B | V35: A | W35: A | X35: B | Y35: =(COUNTIF(E35:X35,"A")+COUNTIF(E35:X35,"B"))/20 -> 1 | Z35: =IF(ISBLANK(E35),"",IF(E35=Truth!B$24,1,0)) -> 1 | AA35: =IF(ISBLANK(F35),"",IF(F35=Truth!C$24,1,0)) -> 1 | AB35: =IF(ISBLANK(G35),"",IF(G35=Truth!D$24,1,0)) -> 1 | AC35: =IF(ISBLANK(H35),"",IF(H35=Truth!E$24,1,0)) -> 0 | AD35: =IF(ISBLANK(I35),"",IF(I35=Truth!F$24,1,0)) -> 1 | AE35: =IF(ISBLANK(J35),"",IF(J35=Truth!G$24,1,0)) -> 1 | AF35: =IF(ISBLANK(K35),"",IF(K35=Truth!H$24,1,0)) -> 1 | AG35: =IF(ISBLANK(L35),"",IF(L35=Truth!I$24,1,0)) -> 1 | ... AS35: =IF(ISBLANK(X35),"",IF(X35=Truth!U$24,1,0)) -> 0 | AT35: =AVERAGE(Z35:AS35) -> 0.8 | AU35: {=SUM(N(LEN(TRIM(Z35:AS35))>0))} -> 20 | AV35: =sum(Z35:AS35) -> 16
A36: P35 | B36: =IF(COUNTIF('Fieldwork W1'!$A$4:$A$22, A36) > 0, "1", IF(COUNTIF('Fieldwork W1'!$A$28:$A$46, A36) > 0, "2", "")) -> 1 | C36: =IF(COUNTIF('Fieldwork W2'!$A$4:$A$22, A36) > 0, "1", IF(COUNTIF('Fieldwork W2'!$A$28:$A$46, A36) > 0, "2", "")) -> 2 | D36: =B36&C36 -> 12 | E36: B | F36: B | G36: A | H36: A | I36: A | J36: B | K36: A | L36: B | M36: A | N36: B | O36: A | P36: A | Q36: B | R36: A | T36: B | U36: A | V36: A | W36: A | X36: A | Y36: =(COUNTIF(E36:X36,"A")+COUNTIF(E36:X36,"B"))/20 -> 0.95 | Z36: =IF(ISBLANK(E36),"",IF(E36=Truth!B$22,1,0)) -> 0 | AA36: =IF(ISBLANK(F36),"",IF(F36=Truth!C$22,1,0)) -> 1 | AB36: =IF(ISBLANK(G36),"",IF(G36=Truth!D$22,1,0)) -> 0 | AC36: =IF(ISBLANK(H36),"",IF(H36=Truth!E$22,1,0)) -> 0 | AD36: =IF(ISBLANK(I36),"",IF(I36=Truth!F$22,1,0)) -> 1 | AE36: =IF(ISBLANK(J36),"",IF(J36=Truth!G$22,1,0)) -> 0 | AF36: =IF(ISBLANK(K36),"",IF(K36=Truth!H$22,1,0)) -> 1 | AG36: =IF(ISBLANK(L36),"",IF(L36=Truth!I$22,1,0)) -> 1 | ... AS36: =IF(ISBLANK(X36),"",IF(X36=Truth!U$22,1,0)) -> 1 | AT36: =AVERAGE(Z36:AS36) -> 0.52631579 | AU36: {=SUM(N(LEN(TRIM(Z36:AS36))>0))} -> 19 | AV36: =sum(Z36:AS36) -> 10
A37: P36 | B37: =IF(COUNTIF('Fieldwork W1'!$A$4:$A$22, A37) > 0, "1", IF(COUNTIF('Fieldwork W1'!$A$28:$A$46, A37) > 0, "2", "")) -> 2 | C37: =IF(COUNTIF('Fieldwork W2'!$A$4:$A$22, A37) > 0, "1", IF(COUNTIF('Fieldwork W2'!$A$28:$A$46, A37) > 0, "2", "")) -> 1 | D37: =B37&C37 -> 21 | E37: A | F37: B | G37: B | H37: B | I37: A | J37: A | L37: B | M37: A | N37: A | O37: B | P37: A | Q37: B | R37: A | S37: B | T37: A | U37: A | V37: A | W37: A | X37: A | Y37: =(COUNTIF(E37:X37,"A")+COUNTIF(E37:X37,"B"))/20 -> 0.95 | Z37: =IF(ISBLANK(E37),"",IF(E37=Truth!B$23,1,0)) -> 1 | AA37: =IF(ISBLANK(F37),"",IF(F37=Truth!C$23,1,0)) -> 1 | AB37: =IF(ISBLANK(G37),"",IF(G37=Truth!D$23,1,0)) -> 1 | AC37: =IF(ISBLANK(H37),"",IF(H37=Truth!E$23,1,0)) -> 1 | AD37: =IF(ISBLANK(I37),"",IF(I37=Truth!F$23,1,0)) -> 1 | AE37: =IF(ISBLANK(J37),"",IF(J37=Truth!G$23,1,0)) -> 1 | AF37: =IF(ISBLANK(K37),"",IF(K37=Truth!H$23,1,0)) | AG37: =IF(ISBLANK(L37),"",IF(L37=Truth!I$23,1,0)) -> 1 | ... AS37: =IF(ISBLANK(X37),"",IF(X37=Truth!U$23,1,0)) -> 1 | AT37: =AVERAGE(Z37:AS37) -> 0.84210526 | AU37: {=SUM(N(LEN(TRIM(Z37:AS37))>0))} -> 19 | AV37: =sum(Z37:AS37) -> 16
A38: P37 | B38: =IF(COUNTIF('Fieldwork W1'!$A$4:$A$22, A38) > 0, "1", IF(COUNTIF('Fieldwork W1'!$A$28:$A$46, A38) > 0, "2", "")) -> 1 | C38: =IF(COUNTIF('Fieldwork W2'!$A$4:$A$22, A38) > 0, "1", IF(COUNTIF('Fieldwork W2'!$A$28:$A$46, A38) > 0, "2", "")) -> 2 | D38: =B38&C38 -> 12 | L38: B | N38: A | O38: A | P38: B | Q38: A | R38: A | S38: A | T38: B | U38: B | V38: A | X38: A | Y38: =(COUNTIF(E38:X38,"A")+COUNTIF(E38:X38,"B"))/20 -> 0.55 | Z38: =IF(ISBLANK(E38),"",IF(E38=Truth!B$24,1,0)) | AA38: =IF(ISBLANK(F38),"",IF(F38=Truth!C$24,1,0)) | AB38: =IF(ISBLANK(G38),"",IF(G38=Truth!D$24,1,0)) | AC38: =IF(ISBLANK(H38),"",IF(H38=Truth!E$24,1,0)) | AD38: =IF(ISBLANK(I38),"",IF(I38=Truth!F$24,1,0)) | AE38: =IF(ISBLANK(J38),"",IF(J38=Truth!G$24,1,0)) | AF38: =IF(ISBLANK(K38),"",IF(K38=Truth!H$24,1,0)) | AG38: =IF(ISBLANK(L38),"",IF(L38=Truth!I$24,1,0)) -> 1 | ... AS38: =IF(ISBLANK(X38),"",IF(X38=Truth!U$24,1,0)) -> 1 | AT38: =AVERAGE(Z38:AS38) -> 0.90909091 | AU38: {=SUM(N(LEN(TRIM(Z38:AS38))>0))} -> 11 | AV38: =sum(Z38:AS38) -> 10
A39: P38 | B39: =IF(COUNTIF('Fieldwork W1'!$A$4:$A$22, A39) > 0, "1", IF(COUNTIF('Fieldwork W1'!$A$28:$A$46, A39) > 0, "2", "")) -> 1 | C39: =IF(COUNTIF('Fieldwork W2'!$A$4:$A$22, A39) > 0, "1", IF(COUNTIF('Fieldwork W2'!$A$28:$A$46, A39) > 0, "2", "")) -> 1 | D39: =B39&C39 -> 11 | E39: B | F39: B | G39: B | H39: B | I39: A | J39: A | K39: A | L39: B | M39: A | N39: B | O39: B | Q39: B | T39: A | U39: B | V39: A | W39: B | X39: A | Y39: =(COUNTIF(E39:X39,"A")+COUNTIF(E39:X39,"B"))/20 -> 0.85 | Z39: =IF(ISBLANK(E39),"",IF(E39=Truth!B$23,1,0)) -> 0 | AA39: =IF(ISBLANK(F39),"",IF(F39=Truth!C$23,1,0)) -> 1 | AB39: =IF(ISBLANK(G39),"",IF(G39=Truth!D$23,1,0)) -> 1 | AC39: =IF(ISBLANK(H39),"",IF(H39=Truth!E$23,1,0)) -> 1 | AD39: =IF(ISBLANK(I39),"",IF(I39=Truth!F$23,1,0)) -> 1 | AE39: =IF(ISBLANK(J39),"",IF(J39=Truth!G$23,1,0)) -> 1 | AF39: =IF(ISBLANK(K39),"",IF(K39=Truth!H$23,1,0)) -> 1 | AG39: =IF(ISBLANK(L39),"",IF(L39=Truth!I$23,1,0)) -> 1 | ... AS39: =IF(ISBLANK(X39),"",IF(X39=Truth!U$23,1,0)) -> 1 | AT39: =AVERAGE(Z39:AS39) -> 0.94117647 | AU39: {=SUM(N(LEN(TRIM(Z39:AS39))>0))} -> 17 | AV39: =sum(Z39:AS39) -> 16

Sheet Truth
A1: Week 1
A2: Ground Truth G1
A3: c1 | B3: c2 | C3: c3 | D3: c4 | E3: c5 | F3: c6 | G3: c7 | H3: c8 | I3: c9 | J3: c10
A4: verdadero | B4: falso | C4: falso | D4: falso | E4: verdadero | F4: verdadero | G4: verdadero | H4: falso | I4: verdadero | J4: falso
A5: A | B5: B | C5: B | D5: B | E5: A | F5: A | G5: A | H5: B | I5: A | J5: B
A6: Ground Truth G2
A7: c1 | B7: c2 | C7: c3 | D7: c4 | E7: c5 | F7: c6 | G7: c7 | H7: c8 | I7: c9 | J7: c10
A8: verdadero | B8: falso | C8: falso | D8: falso | E8: verdadero | F8: verdadero | G8: falso | H8: falso | I8: verdadero | J8: verdadero
A9: A | B9: B | C9: B | D9: B | E9: A | F9: A | G9: B | H9: B | I9: A | J9: A
A11: Week 2
A12: Ground Truth G1
A13: c1 | B13: c2 | C13: c3 | D13: c4 | E13: c5 | F13: c6 | G13: c7 | H13: c8 | I13: c9 | J13: c10
A14: Verdadero | B14: Falso | C14: Verdadero | D14: Falso | E14: Verdadero | F14: Falso ? | G14: Falso | H14: Verdadero | I14: Falso - Debatible | J14: Verdadero
A15: A | B15: B | C15: A | D15: B | E15: A | F15: B | G15: B | H15: A | I15: B | J15: A
A16: Ground Truth G2
A17: c1 | B17: c2 | C17: c3 | D17: c4 | E17: c5 | F17: c6 | G17: c7 | H17: c8 | I17: c9 | J17: c10
A18: Falso | B18: Verdadero | C18: Falso | D18: Verdadero | E18: Falso | F18: Verdadero | G18: Falso | H18: Verdadero | I18: Falso - Debatible | J18: Verdadero
A19: B | B19: A | C19: B | D19: A | E19: B | F19: A | G19: B | H19: A | I19: B | J19: A
A21: Ground Truth of the Content | B21: c1 | C21: c2 | D21: c3 | E21: c4 | F21: c5 | G21: c6 | H21: c7 | I21: c8 | J21: c9 | K21: c10 | L21: c11 | M21: c12 | N21: c13 | O21: c14 | P21: c15 | Q21: c16 | R21: c17 | S21: c18 | T21: c19 | U21: c20
A22: 11 | B22: A | C22: B | D22: B | E22: B | F22: A | G22: A | H22: A | I22: B | J22: A | K22: B | L22: A | M22: B | N22: A | O22: B | P22: A | Q22: B | R22: B | S22: A | T22: B | U22: A
A23: 12 | B23: A | C23: B | D23: B | E23: B | F23: A | G23: A | H23: A | I23: B | J23: A | K23: B | L23: B | M23: A | N23: B | O23: A | P23: B | Q23: A | R23: B | S23: A | T23: B | U23: A
A24: 21 | B24: A | C24: B | D24: B | E24: B | F24: A | G24: A | H24: B | I24: B | J24: A | K24: A | L24: A | M24: B | N24: A | O24: B | P24: A | Q24: B | R24: B | S24: A | T24: B | U24: A
A25: 22 | B25: A | C25: B | D25: B | E25: B | F25: A | G25: A | H25: B | I25: B | J25: A | K25: A | L25: B | M25: A | N25: B | O25: A | P25: B | Q25: A | R25: B | S25: A | T25: B | U25: A

Sheet content
A1: ID | B1: Media Name | C1: Truth Value | D1: Topic | E1: Modality | F1: Short description | G1: Fact-check source
A2: 1 | B2: c1_G1W1_real | C2: Real | D2: National News | E2: Image | F2: Screenshot of a RRSS post claiming Colombia is the country woth most tolls in Latinamerica
A3: 2 | B3: c2_G1W1_fake | C3: Fake | D3: Fear monguering | E3: Image | F3: Screenshot of a WhatsApp story showing the face of 4 men that allegedly are kidnapping kids from schools and houses. | G3: (3) Cazadores de Fake News en X: "No es cierta la cadena de Whatsapp que advierte sobre una banda dedicada al robo de niños y tráfico de órganos La imagen con la cara de los supuestos secuestradores de niños y traficantes de órganos ha circulado en distintos países latinoamericanos desde el año 2016. La alerta https://t.co/e0U3lS2XZ8" / X
A4: 3 | B4: c3_G1W1_fake | C4: Fake | D4: Conspiracy | E4: Image | F4: Conspiracy infographic about "the real 2030 agenda", which change each ODS: "1. Reducing population, ... 3. Abortion and contraception..."
A5: 4 | B5: c4_G1W1_fake | C5: Fake | D5: Health | E5: Video | F5: A doctor claiming that dengue fever is caused by a lack of calcium and should be treated with calcium and vitamin D supplements. | G5: Es falso que el dengue “se da por falta de calcio” y “se cura con vitamina D” como asegura un video viral - Chequeado
A6: 5 | B6: c5_G1W1_real | C6: Real | D6: Nature | E6: Text | F6: Text chain warning about the impacts of installing hummingbird feeders and recommending flowers instead.
A7: 6 | B7: c6_G1W1_real | C7: Real | D7: National News | E7: Image | F7: Information table showing the different minimum wage rates in Colombia for 2025.
A8: 7 | B8: c7_G1W1_real | C8: Real | D8: Regional News | E8: Video | F8: Journalistic format about the new traffic barriers that the Department of Mobility in Cali, Colombia, would use.
A9: 8 | B9: c8_G1W1_fake | C9: Fake | D9: Political | E9: Image | F9: Screenshot of an alleged tweet from former Colombian President Ivan Duque, in which he acknowledged an alleged drug trafficker as his campaign financier. | G9: https://www.lasillavacia.com/detector-de-mentiras/falso/detector-de-nuevo-duque-no-lamento-la-muerte-del-nene-hernandez/
A10: 9 | B10: c9_G1W1_real | C10: Real | D10: Regional/National News | E10: Text + Image | F10: News article about the capture of a military-linked gang that provided support to illegal armed groups.
A11: 10 | B11: c10_G1W1_fake | C11: Fake | D11: Fear monguering | E11: Text | F11: A message about an alleged new telephone crime, in which if the person answers a call or text, their SIM card will be automatically duplicated. | G11: https://www.animalpolitico.com/verificacion-de-hechos/fact-checking/llamada-inviable-no-puede-robar-sim?utm_source=chatgpt.com https://efectococuyo.com/cocuyo-chequea/cicpc-alerta-metodos-estafa-falso/?utm_source=chatgpt.com
A12: 11 | B12: c1_G2W1_real | C12: Real | D12: Informative | E12: Image | F12: Infographic about what to do during a flood if in a vehicle
A13: 12 | B13: c2_G2W1_fake | C13: Fake | D13: Health | E13: Image | F13: An infographic-style post purportedly contains information on the number of deaths and adverse effects from COVID-19 vaccines, claiming that this is not a respiratory virus but poisoning.
A14: 13 | B14: c3_G2W1_fake | C14: Fake | D14: Fear monguering | E14: Image | F14: Screenshot of a WhatsApp status with supposed information "direct from prison," in which a prisoner warns about an order to steal children.
A15: 14 | B15: c4_G2W1_fake | C15: Fake | D15: Regional/National News | E15: Video | F15: A citizen at a toll booth claims that a supposed "Law 769 of 2002" dictates that after waiting five minutes, you don't have to pay a toll. This law doesn't exist, but in the video, they let him go without paying. | G15: ley-769-de-2002-codigo-nacional-de-transito_3704_0.pdf
A16: 15 | B16: c5_G2W1_real | C16: Real | D16: Health | E16: Text | F16: A chain message with recommendations that frames good health practices such as physical exercise or eating fruits and vegetables as "medicine."
A17: 16 | B17: c6_G2W1_real | C17: Real | D17: National News | E17: Video | F17: Official informational video about a line of associative credit offered by a government agency.
A18: 17 | B18: c7_G2W1_fake | C18: Fake | D18: Political | E18: Image | F18: Bar chart with inaccurate and/or false information showing the number of on-duty deaths of members of the public force during three presidential terms in Colombia.
A19: 18 | B19: c8_G2W1_fake | C19: Fake | D19: Informative | E19: Image | F19: Screenshot of a post stating that when withdrawing funds from an ATM, pressing "cancel" twice prevents data theft.
A20: 19 | B20: c9_G2W1_real | C20: Real | D20: Health | E20: Video | F20: A doctor reports on the symptoms of a cerebral stroke to learn how to recognize and treat them.
A21: 20 | B21: c10_G2W1_real | C21: Real | D21: Nature | E21: Text + Image | F21: Message informing about opossums, their ecosystem benefits, and recommending respecting their lives.
A22: 21 | B22: c1_G1W2_real | C22: Real | D22: National News (Information) | E22: Image | F22: Image containing Article 199 of the Colombian Political Constitution.
A23: 22 | B23: c2_G1W2_fake | C23: Fake | D23: Fear monguering | E23: Video | F23: Video of a young man putting on a mask, with a message warning that these are the masks that "Venezuelans (immigrants) are using to rob."
A24: 23 | B24: c3_G1W2_real | C24: Real | D24: National News | E24: Video | F24: An influencer reporting on a government technology training program based on virtual courses.
A25: 24 | B25: c4_G1W2_fake | C25: Fake | D25: Political | E25: Video | F25: A series of fake or hard-to-confirm anti-right political propaganda images, accompanied by a background speech by Frédéric Bastiat and delivered by an unknown host.
